2025-06-23 21:34:46,983 - INFO - Logging initialized. Log file: logs/rag_evaluation_20250623_213446.log
2025-06-23 21:34:46,983 - INFO - üéØ Starting RAG Evaluation Pipeline
2025-06-23 21:34:46,983 - INFO - ================================================================================
2025-06-23 21:34:46,983 - INFO - üîç Step 1: Environment Validation
2025-06-23 21:34:46,986 - INFO - ‚úÖ Environment validation passed
2025-06-23 21:34:46,986 - INFO - 
‚è≠Ô∏è  Step 2: Skipping Docker service management (--skip-services)
2025-06-23 21:34:46,986 - INFO - 
üöÄ Step 3: Pipeline Execution
2025-06-23 21:34:46,986 - INFO - üöÄ Starting Main E2E Pipeline...
2025-06-23 21:34:50,078 - ERROR - ‚ùå Main E2E Pipeline failed with return code 1
2025-06-23 21:34:50,078 - ERROR - Error output: 2025-06-23 21:34:49,378 - INFO - ‚úÖ Phoenix tracing configured for project: retrieval-evaluation-20250623_213449
2025-06-23 21:34:49,512 - INFO - üì• Loading and processing data...
2025-06-23 21:34:49,514 - INFO - üîß Setting up vector stores...
2025-06-23 21:34:49,524 - ERROR - ‚ùå Error during execution: [Errno 111] Connect call failed ('127.0.0.1', 6024)
2025-06-23 21:34:49,524 - INFO - üîÑ Cleanup completed
Traceback (most recent call last):
  File "<frozen runpy>", line 198, in _run_module_as_main
  File "<frozen runpy>", line 88, in _run_code
  File "/home/donbr/validation/rag-eval-foundations/src/langchain_eval_foundations_e2e.py", line 306, in <module>
    asyncio.run(main())
    ~~~~~~~~~~~^^^^^^^^
  File "/home/donbr/.local/share/uv/python/cpython-3.13.2-linux-x86_64-gnu/lib/python3.13/asyncio/runners.py", line 195, in run
    return runner.run(main)
           ~~~~~~~~~~^^^^^^
  File "/home/donbr/.local/share/uv/python/cpython-3.13.2-linux-x86_64-gnu/lib/python3.13/asyncio/runners.py", line 118, in run
    return self._loop.run_until_complete(task)
           ~~~~~~~~~~~~~~~~~~~~~~~~~~~~~^^^^^^
  File "/home/donbr/.local/share/uv/python/cpython-3.13.2-linux-x86_64-gnu/lib/python3.13/asyncio/base_events.py", line 725, in run_until_complete
    return future.result()
           ~~~~~~~~~~~~~^^
  File "/home/donbr/validation/rag-eval-foundations/src/langchain_eval_foundations_e2e.py", line 259, in main
    baseline_vectorstore = await setup_vector_store(config, config.table_baseline, embeddings)
                           ^^^^^^^^^^^^^^^^^^^^^^^^^^^^^^^^^^^^^^^^^^^^^^^^^^^^^^^^^^^^^^^^^^^
  File "/home/donbr/validation/rag-eval-foundations/src/langchain_eval_foundations_e2e.py", line 117, in setup_vector_store
    await pg_engine.ainit_vectorstore_table(
    ...<3 lines>...
    )
  File "/home/donbr/validation/rag-eval-foundations/.venv/lib/python3.13/site-packages/langchain_postgres/v2/engine.py", line 284, in ainit_vectorstore_table
    await self._run_as_async(
    ...<12 lines>...
    )
  File "/home/donbr/validation/rag-eval-foundations/.venv/lib/python3.13/site-packages/langchain_postgres/v2/engine.py", line 119, in _run_as_async
    return await asyncio.wrap_future(
           ^^^^^^^^^^^^^^^^^^^^^^^^^^
        asyncio.run_coroutine_threadsafe(coro, self._loop)
        ^^^^^^^^^^^^^^^^^^^^^^^^^^^^^^^^^^^^^^^^^^^^^^^^^^
    )
    ^
  File "/home/donbr/validation/rag-eval-foundations/.venv/lib/python3.13/site-packages/langchain_postgres/v2/engine.py", line 208, in _ainit_vectorstore_table
    async with self._pool.connect() as conn:
               ~~~~~~~~~~~~~~~~~~^^
  File "/home/donbr/validation/rag-eval-foundations/.venv/lib/python3.13/site-packages/sqlalchemy/ext/asyncio/base.py", line 121, in __aenter__
    return await self.start(is_ctxmanager=True)
           ^^^^^^^^^^^^^^^^^^^^^^^^^^^^^^^^^^^^
  File "/home/donbr/validation/rag-eval-foundations/.venv/lib/python3.13/site-packages/sqlalchemy/ext/asyncio/engine.py", line 274, in start
    await greenlet_spawn(self.sync_engine.connect)
  File "/home/donbr/validation/rag-eval-foundations/.venv/lib/python3.13/site-packages/sqlalchemy/util/_concurrency_py3k.py", line 201, in greenlet_spawn
    result = context.throw(*sys.exc_info())
  File "/home/donbr/validation/rag-eval-foundations/.venv/lib/python3.13/site-packages/sqlalchemy/engine/base.py", line 3273, in connect
    return self._connection_cls(self)
           ~~~~~~~~~~~~~~~~~~~~^^^^^^
  File "/home/donbr/validation/rag-eval-foundations/.venv/lib/python3.13/site-packages/sqlalchemy/engine/base.py", line 145, in __init__
    self._dbapi_connection = engine.raw_connection()
                             ~~~~~~~~~~~~~~~~~~~~~^^
  File "/home/donbr/validation/rag-eval-foundations/.venv/lib/python3.13/site-packages/sqlalchemy/engine/base.py", line 3297, in raw_connection
    return self.pool.connect()
           ~~~~~~~~~~~~~~~~~^^
  File "/home/donbr/validation/rag-eval-foundations/.venv/lib/python3.13/site-packages/sqlalchemy/pool/base.py", line 449, in connect
    return _ConnectionFairy._checkout(self)
           ~~~~~~~~~~~~~~~~~~~~~~~~~~^^^^^^
  File "/home/donbr/validation/rag-eval-foundations/.venv/lib/python3.13/site-packages/sqlalchemy/pool/base.py", line 1264, in _checkout
    fairy = _ConnectionRecord.checkout(pool)
  File "/home/donbr/validation/rag-eval-foundations/.venv/lib/python3.13/site-packages/sqlalchemy/pool/base.py", line 713, in checkout
    rec = pool._do_get()
  File "/home/donbr/validation/rag-eval-foundations/.venv/lib/python3.13/site-packages/sqlalchemy/pool/impl.py", line 179, in _do_get
    with util.safe_reraise():
         ~~~~~~~~~~~~~~~~~^^
  File "/home/donbr/validation/rag-eval-foundations/.venv/lib/python3.13/site-packages/sqlalchemy/util/langhelpers.py", line 224, in __exit__
    raise exc_value.with_traceback(exc_tb)
  File "/home/donbr/validation/rag-eval-foundations/.venv/lib/python3.13/site-packages/sqlalchemy/pool/impl.py", line 177, in _do_get
    return self._create_connection()
           ~~~~~~~~~~~~~~~~~~~~~~~^^
  File "/home/donbr/validation/rag-eval-foundations/.venv/lib/python3.13/site-packages/sqlalchemy/pool/base.py", line 390, in _create_connection
    return _ConnectionRecord(self)
  File "/home/donbr/validation/rag-eval-foundations/.venv/lib/python3.13/site-packages/sqlalchemy/pool/base.py", line 675, in __init__
    self.__connect()
    ~~~~~~~~~~~~~~^^
  File "/home/donbr/validation/rag-eval-foundations/.venv/lib/python3.13/site-packages/sqlalchemy/pool/base.py", line 901, in __connect
    with util.safe_reraise():
         ~~~~~~~~~~~~~~~~~^^
  File "/home/donbr/validation/rag-eval-foundations/.venv/lib/python3.13/site-packages/sqlalchemy/util/langhelpers.py", line 224, in __exit__
    raise exc_value.with_traceback(exc_tb)
  File "/home/donbr/validation/rag-eval-foundations/.venv/lib/python3.13/site-packages/sqlalchemy/pool/base.py", line 897, in __connect
    self.dbapi_connection = connection = pool._invoke_creator(self)
                                         ~~~~~~~~~~~~~~~~~~~~^^^^^^
  File "/home/donbr/validation/rag-eval-foundations/.venv/lib/python3.13/site-packages/sqlalchemy/engine/create.py", line 646, in connect
    return dialect.connect(*cargs, **cparams)
           ~~~~~~~~~~~~~~~^^^^^^^^^^^^^^^^^^^
  File "/home/donbr/validation/rag-eval-foundations/.venv/lib/python3.13/site-packages/sqlalchemy/engine/default.py", line 625, in connect
    return self.loaded_dbapi.connect(*cargs, **cparams)  # type: ignore[no-any-return]  # NOQA: E501
           ~~~~~~~~~~~~~~~~~~~~~~~~~^^^^^^^^^^^^^^^^^^^
  File "/home/donbr/validation/rag-eval-foundations/.venv/lib/python3.13/site-packages/sqlalchemy/dialects/postgresql/asyncpg.py", line 961, in connect
    await_only(creator_fn(*arg, **kw)),
    ~~~~~~~~~~^^^^^^^^^^^^^^^^^^^^^^^^
  File "/home/donbr/validation/rag-eval-foundations/.venv/lib/python3.13/site-packages/sqlalchemy/util/_concurrency_py3k.py", line 132, in await_only
    return current.parent.switch(awaitable)  # type: ignore[no-any-return,attr-defined] # noqa: E501
           ~~~~~~~~~~~~~~~~~~~~~^^^^^^^^^^^
  File "/home/donbr/validation/rag-eval-foundations/.venv/lib/python3.13/site-packages/sqlalchemy/util/_concurrency_py3k.py", line 196, in greenlet_spawn
    value = await result
            ^^^^^^^^^^^^
  File "/home/donbr/validation/rag-eval-foundations/.venv/lib/python3.13/site-packages/asyncpg/connection.py", line 2421, in connect
    return await connect_utils._connect(
           ^^^^^^^^^^^^^^^^^^^^^^^^^^^^^
    ...<20 lines>...
    )
    ^
  File "/home/donbr/validation/rag-eval-foundations/.venv/lib/python3.13/site-packages/asyncpg/connect_utils.py", line 1075, in _connect
    raise last_error or exceptions.TargetServerAttributeNotMatched(
    ...<2 lines>...
    )
  File "/home/donbr/validation/rag-eval-foundations/.venv/lib/python3.13/site-packages/asyncpg/connect_utils.py", line 1049, in _connect
    conn = await _connect_addr(
           ^^^^^^^^^^^^^^^^^^^^
    ...<6 lines>...
    )
    ^
  File "/home/donbr/validation/rag-eval-foundations/.venv/lib/python3.13/site-packages/asyncpg/connect_utils.py", line 886, in _connect_addr
    return await __connect_addr(params, True, *args)
           ^^^^^^^^^^^^^^^^^^^^^^^^^^^^^^^^^^^^^^^^^
  File "/home/donbr/validation/rag-eval-foundations/.venv/lib/python3.13/site-packages/asyncpg/connect_utils.py", line 931, in __connect_addr
    tr, pr = await connector
             ^^^^^^^^^^^^^^^
  File "/home/donbr/validation/rag-eval-foundations/.venv/lib/python3.13/site-packages/asyncpg/connect_utils.py", line 802, in _create_ssl_connection
    tr, pr = await loop.create_connection(
             ^^^^^^^^^^^^^^^^^^^^^^^^^^^^^
    ...<2 lines>...
        host, port)
        ^^^^^^^^^^^
  File "/home/donbr/.local/share/uv/python/cpython-3.13.2-linux-x86_64-gnu/lib/python3.13/asyncio/base_events.py", line 1166, in create_connection
    raise exceptions[0]
  File "/home/donbr/.local/share/uv/python/cpython-3.13.2-linux-x86_64-gnu/lib/python3.13/asyncio/base_events.py", line 1141, in create_connection
    sock = await self._connect_sock(
           ^^^^^^^^^^^^^^^^^^^^^^^^^
        exceptions, addrinfo, laddr_infos)
        ^^^^^^^^^^^^^^^^^^^^^^^^^^^^^^^^^^
  File "/home/donbr/.local/share/uv/python/cpython-3.13.2-linux-x86_64-gnu/lib/python3.13/asyncio/base_events.py", line 1044, in _connect_sock
    await self.sock_connect(sock, address)
  File "/home/donbr/.local/share/uv/python/cpython-3.13.2-linux-x86_64-gnu/lib/python3.13/asyncio/selector_events.py", line 641, in sock_connect
    return await fut
           ^^^^^^^^^
  File "/home/donbr/.local/share/uv/python/cpython-3.13.2-linux-x86_64-gnu/lib/python3.13/asyncio/selector_events.py", line 681, in _sock_connect_cb
    raise OSError(err, f'Connect call failed {address}')
ConnectionRefusedError: [Errno 111] Connect call failed ('127.0.0.1', 6024)

2025-06-23 21:34:50,078 - ERROR - ‚ùå Main E2E Pipeline failed. Stopping pipeline execution.
2025-06-23 21:34:50,078 - INFO - 
================================================================================
2025-06-23 21:34:50,078 - INFO - üéØ RAG EVALUATION PIPELINE SUMMARY
2025-06-23 21:34:50,078 - INFO - ================================================================================
2025-06-23 21:34:50,078 - INFO - üìä Execution Summary:
2025-06-23 21:34:50,079 - INFO -    Total Steps: 1
2025-06-23 21:34:50,079 - INFO -    Successful: 0
2025-06-23 21:34:50,079 - INFO -    Failed: 1
2025-06-23 21:34:50,079 - INFO -    Total Time: 3.1s (0.1 minutes)
2025-06-23 21:34:50,079 - INFO - 
üìã Step Details:
2025-06-23 21:34:50,079 - INFO -    Main E2E Pipeline                        ‚ùå FAILED
2025-06-23 21:34:50,079 - INFO - 
‚ö†Ô∏è  PIPELINE COMPLETED WITH ERRORS
2025-06-23 21:34:50,079 - INFO -    Check the logs above for error details
2025-06-23 21:34:50,079 - INFO -    Fix issues and re-run the failed steps
